Workbook

Sheet Phase Estimation
A1: Phase | B1: Task ID | C1: Task | D1: Description | E1: Assign to | F1: Est. Days | G1: Buffer 20% | H1: Total Days | I1: Est. Weeks | J1: Cost | K1: Comments
A2: Phase 0 — Design & Setup
B3: 0.1 | C3: UI/UX Wireframes | D3: Wireframes for all 6 views (Finder, Roster, Pipeline, Deals, Patterns, Admin), creator detail, proposal flow, dashboard mockups, approval workflow UI, mobile responsive, client sign-off | E3: Mansour | F3: 8 | G3: =F3*0.2 -> 1.6 | H3: =F3+G3 -> 9.6 | I3: =H3/5 -> 1.92
B4: 0.2 | C4: Process Flow Diagrams | D4: Proposal lifecycle, AI recommendation flow, approval workflow, rate card calculation, social data refresh, creator onboarding, media kit extraction | E4: Ghassan | F4: 2 | G4: =F4*0.2 -> 0.4 | H4: =F4+G4 -> 2.4 | I4: =H4/5 -> 0.48
B5: 0.3 | C5: VPortal API preperation | D5: Document cross-schema dependencies (Supplier, Client, BU, Project, ProjectLine, Item), confirm Identity/JWT sharing, confirm SignalR, document needed API calls | E5: Ghassan | F5: 0.2 | G5: =F5*0.2 -> 0.04 | H5: =F5+G5 -> 0.24 | I5: =H5/5 -> 0.048 | K5: GS: already working on it for AI integration
B6: 0.4 | C6: Solution Structure Setup | D6: Backend module structure, React app scaffold (Vite/MUI6), wire auth, Azure Blob containers, CI/CD pipeline | E6: Barzan | F6: 1 | G6: =F6*0.2 -> 0.2 | H6: =F6+G6 -> 1.2 | I6: =H6/5 -> 0.24
B7: 0.5 | C7: Sentry Monitoring | D7: Error tracking for API and AI failures, alert routing, performance monitoring | E7: Barzan | F7: 0.5 | G7: =F7*0.2 -> 0.1 | H7: =F7+G7 -> 0.6 | I7: =H7/5 -> 0.12
C8: Phase 0 Subtotal | F8: =SUM(F3:F7) -> 11.7 | G8: =F8*0.2 -> 2.34 | H8: =F8+G8 -> 14.04 | I8: =H8/5 -> 2.808 | J8: =I8*Variables!$B$3*Variables!$B$1 -> 1965.6
A9: Phase 1 — Core VCI Platform (without AI)
A10: 1.1 | C10: Creator Feature | F10: =SUM(F11:F18) -> 5.6 | G10: =SUM(G11:G18) -> 1.12 | H10: =SUM(H11:H18) -> 6.72 | I10: =SUM(I11:I18) -> 1.344
A11: 1.1 | B11: 1.1a | C11: Creator Entity Layer | D11: CreatorSocialMetrics, CreatorRateCard, CreatorTravelCosts, CreatorBrandConflict, CreatorTierConfig, SavedSearch, DeliverableWeightConfig, DeliverableTitleMapping entities + EF migrations | E11: AI | F11: 0.3 | G11: =F11*0.2 -> 0.06 | H11: =F11+G11 -> 0.36 | I11: =H11/5 -> 0.072
A12: 1.1 | B12: 1.1b | C12: Creator API Endpoints | D12: All /api/v1/creators/* endpoints: CRUD, search, filters, import, rate cards, travel costs, brand conflicts, tier config, weights, mappings, saved searches, data completion | E12: AI | F12: 0.3 | G12: =F12*0.2 -> 0.06 | H12: =F12+G12 -> 0.36 | I12: =H12/5 -> 0.072
A13: 1.1 | B13: 1.1c | C13: Social Data Integration | D13: Social Blade wiring to CreatorSocialMetrics, Phyllo public data client, Apify fallback, nightly batch job, on-demand refresh | E13: Dev X | F13: 1.2 | G13: =F13*0.2 -> 0.24 | H13: =F13+G13 -> 1.44 | I13: =H13/5 -> 0.288
A14: 1.1 | B14: 1.1d | C14: Creator Roster | D14: Roster list view with filters + free text search, saved search presets, creator detail view (profile, social metrics, social links), Data completion tracker (21 fields, fill rates, color-coded), Media kit upload + storage | E14: Dev X | F14: 1 | G14: =F14*0.2 -> 0.2 | H14: =F14+G14 -> 1.2 | I14: =H14/5 -> 0.24
A15: 1.1 | B15: 1.1e | C15: Rate Card | D15: Rate card tab in creator detail (CRUD, base/min/max, AED/USD toggle), bulk rate review/approval screen, deliverable weight config page, title mapping page | E15: Dev X | F15: 0.8 | G15: =F15*0.2 -> 0.16 | H15: =F15+G15 -> 0.96 | I15: =H15/5 -> 0.192
A16: 1.1 | B16: 1.1f | C16: Rate Calculation Engine | D16: Historical rate calculation from PM ProjectLine data, deliverable title mapping (auto + manual), weight matrix decomposition, currency normalization, scheduled recalculation | E16: Ghassan/Dev X | F16: 1 | G16: =F16*0.2 -> 0.2 | H16: =F16+G16 -> 1.2 | I16: =H16/5 -> 0.24
A17: 1.1 | B17: 1.1g | C17: Bulk Import Creator | D17: CSV/Excel import with template download, validation, preview, error reporting, auto social fetch. | E17: Dev X | F17: 0.5 | G17: =F17*0.2 -> 0.1 | H17: =F17+G17 -> 0.6 | I17: =H17/5 -> 0.12
A18: 1.1 | B18: 1.1h | C18: Travel Costs | D18: Travel costs CRUD for non-UAE creators | E18: Dev X | F18: 0.5 | G18: =F18*0.2 -> 0.1 | H18: =F18+G18 -> 0.6 | I18: =H18/5 -> 0.12
A19: 1.2 | C19: Proposal Feature | F19: =SUM(F20:F25) -> 4.5 | G19: =SUM(G20:G25) -> 0.9 | H19: =SUM(H20:H25) -> 5.4 | I19: =SUM(I20:I25) -> 1.08
A20: 1.2 | B20: 1.2a | C20: Proposal Entity Layer | D20: Proposal, ProposalLine, ProposalApproval, ProposalTemplate, ApprovalMatrix entities + EF migrations | E20: AI | F20: 0.3 | G20: =F20*0.2 -> 0.06 | H20: =F20+G20 -> 0.36 | I20: =H20/5 -> 0.072
A21: 1.2 | B21: 1.2b | C21: Proposal API Endpoints | D21: All /api/v1/proposals/* endpoints: CRUD, duplicate, approval actions, won/lost, create-project, document versions. Templates, approval matrix endpoints | E21: AI | F21: 0.4 | G21: =F21*0.2 -> 0.08 | H21: =F21+G21 -> 0.48 | I21: =H21/5 -> 0.096
A22: 1.2 | B22: 1.2c | C22: Proposal Creation | D22: Campaign brief input form (client lookup, BU, budget, platforms, language), manual creator selection from roster, deliverable entry per line, pricing (Amount/Cost/Percentage/Travel), (AI placeholder for phase 2) | E22: Dev X | F22: 1.5 | G22: =F22*0.2 -> 0.3 | H22: =F22+G22 -> 1.8 | I22: =H22/5 -> 0.36
A23: 1.2 | B23: 1.2d | C23: Document Generation | D23: PDF/Word proposal generation using BU templates, multi-language (EN/AR/EN+AR sequential), Azure Blob versioned storage, document preview/download | E23: Dev X | F23: 1 | G23: =F23*0.2 -> 0.2 | H23: =F23+G23 -> 1.2 | I23: =H23/5 -> 0.24
A24: 1.2 | B24: 1.2e | C24: Approval Workflow | D24: Configurable approval matrix (per BU + deal size), multi-step sequential approval, Approve/Reject/RequestChanges with comments, email + in-app notifications | E24: Dev X | F24: 0.5 | G24: =F24*0.2 -> 0.1 | H24: =F24+G24 -> 0.6 | I24: =H24/5 -> 0.12
A25: 1.2 | B25: 1.2f | C25: Proposal Lifecycle | D25: Status transitions (Draft to Won/Lost), won deal tracking (ActualRevenue, WonDate), lost reason, Create Project from Proposal, duplicate, reference numbers | E25: Dev X | F25: 0.8 | G25: =F25*0.2 -> 0.16 | H25: =F25+G25 -> 0.96 | I25: =H25/5 -> 0.192
A26: 1.3 | C26: Dashboard & Reporting | F26: =SUM(F27:F29) -> 3.2 | G26: =SUM(G27:G29) -> 0.64 | H26: =SUM(H27:H29) -> 3.84 | I26: =SUM(I27:I29) -> 0.768
A27: 1.3 | B27: 1.3a | C27: Pipeline Dashboard | D27: Proposal (count + value by status), revenue by client chart, revenue by year chart, role-based views (TM/BU Head/Executive), financial restrictions | E27: Dev X | F27: 1.5 | G27: =F27*0.2 -> 0.3 | H27: =F27+G27 -> 1.8 | I27: =H27/5 -> 0.36
A28: 1.3 | B28: 1.3b | C28: Deals View | D28: Won proposals grouped by client (accordion), KPI cards, revenue by year, inline editing (notes, actual revenue), Create Project button, link to proposal | E28: Dev X | F28: 1.2 | G28: =F28*0.2 -> 0.24 | H28: =F28+G28 -> 1.44 | I28: =H28/5 -> 0.288
A29: 1.3 | B29: 1.3d | C29: Excel Export | D29: Dashboard data export to Excel across all views | E29: Dev X | F29: 0.5 | G29: =F29*0.2 -> 0.1 | H29: =F29+G29 -> 0.6 | I29: =H29/5 -> 0.12
A30: 1.4 | C30: Admin | F30: =SUM(F31:F31) -> 3 | G30: =SUM(G31:G31) -> 0.6 | H30: =SUM(H31:H31) -> 3.6 | I30: =SUM(I31:I31) -> 0.72
A31: 1.4 | B31: 1.4a | C31: Admin | D31: Tier config, weight config, title mapping, template editor, approval matrix config, API key management, data completion overview, AI prompt placeholder (read-only) | E31: Dev X | F31: 3 | G31: =F31*0.2 -> 0.6 | H31: =F31+G31 -> 3.6 | I31: =H31/5 -> 0.72
A32: 1.5 | C32: Testing | F32: =SUM(F33:F33) -> 4 | G32: =SUM(G33:G33) -> 0.8 | H32: =SUM(H33:H33) -> 4.8 | I32: =SUM(I33:I33) -> 0.96
A33: 1.5 | B33: 1.5a | C33: Test Phase 1 | D33: QA test phase 1 | E33: QA X | F33: 4 | G33: =F33*0.2 -> 0.8 | H33: =F33+G33 -> 4.8 | I33: =H33/5 -> 0.96
C34: Phase 1 Subtotal | F34: =F10+F19+F26+F30+F32 -> 20.3 | G34: =F34*0.2 -> 4.06 | H34: =F34+G34 -> 24.36 | I34: =H34/5 -> 4.872 | J34: =I34*Variables!$B$3*Variables!$B$1 -> 3410.4
A35: Phase 2 — AI Integration
A36: 2 | B36: 2.1 | C36: Claude API Service Layer | D36: Claude Sonnet + Haiku API client, authentication, error handling, retry logic, token usage tracking | E36: Ghassan/Dev X | F36: 1 | G36: =F36*0.2 -> 0.2 | H36: =F36+G36 -> 1.2 | I36: =H36/5 -> 0.24 | K36: Will start on it while working on after 2 weeks from phase 1
A37: 2 | B37: 2.2 | C37: AI Brief Expansion | D37: Replace placeholder: rough brief to structured brief (audience, categories, tiers, tone) via Sonnet | E37: Dev X | F37: 2 | G37: =F37*0.2 -> 0.4 | H37: =F37+G37 -> 2.4 | I37: =H37/5 -> 0.48
A38: 2 | B38: 2.3 | C38: AI Creator Ranking | D38: Replace placeholder: brief + roster to scored shortlist with justifications via Sonnet | E38: Dev X | F38: 3 | G38: =F38*0.2 -> 0.6 | H38: =F38+G38 -> 3.6 | I38: =H38/5 -> 0.72
A39: 2 | B39: 2.4 | C39: AI Deliverable Recommendation | D39: AI suggests deliverables per creator based on campaign objectives | E39: Dev X | F39: 1 | G39: =F39*0.2 -> 0.2 | H39: =F39+G39 -> 1.2 | I39: =H39/5 -> 0.24
A40: 2 | B40: 2.5 | C40: AI Narrative Generation | D40: Replace placeholder: generates professional proposal narrative (EN/AR/EN+AR) via Sonnet | E40: Dev X | F40: 1 | G40: =F40*0.2 -> 0.2 | H40: =F40+G40 -> 1.2 | I40: =H40/5 -> 0.24
...

Sheet Open Questions
A1: # | B1: Question | C1: Owner | D1: Status | E1: Priority | F1: Target Phase | G1: Notes
A2: 1 | B2: Social Blade API tier and rate limits — confirm plan details | C2: Ghassan | D2: Open | E2: High | F2: Phase 0
A3: 2 | B3: Specific Apify actors per platform + budget constraints | C3: Ghassan | D3: Open | E3: Medium | F3: Phase 1
A4: 3 | B4: Full list of 10 business unit names and codes | C4: Comms Visioneers | D4: Open | E4: High | F4: Phase 0
A5: 4 | B5: Approval chain definitions per BU — who approves, deal size thresholds | C5: Comms Visioneers | D5: Open | E5: High | F5: Phase 1
A6: 5 | B6: BU template branding assets delivery timeline (logos, colors, fonts) | C6: Comms Visioneers | D6: Open | E6: Medium | F6: Phase 1
A7: 6 | B7: Creator data privacy / consent — legal review needed before client portal | C7: Comms Visioneers | D7: Open | E7: Low | F7: Phase 3
A8: 7 | B8: Deliverable types: 4 simple (Phase 1) or expand to 8? Client to confirm | C8: Comms Visioneers | D8: Open | E8: Medium | F8: Phase 1/3
A9: 8 | B9: Phyllo pricing tier + per-creator costs | C9: Ghassan | D9: Open | E9: High | F9: Phase 0
A10: 9 | B10: Confirm Item master has entries for deliverable types or seed needed | C10: Ghassan | D10: Open | E10: High | F10: Phase 0
A11: 10 | B11: Claude API budget cap — monthly limit for AI features | C11: Ghassan | D11: Open | E11: High | F11: Phase 2
A12: 11 | B12: List of Role allowed in VCI? | C12: Comms Visioneers | D12: Open | E12: High | F12: Phase 0
A13: 12 | B13: PM ProjectLine cost field confirmation — which field stores per-creator cost? | C13: Comms Visioneers | D13: Open | E13: High | F13: Phase 1 | G13: Confirmed: ProjectLine.Cost
A14: 13 | B14: What is the different between Deal and Proposal ? | C14: Comms Visioneers | D14: Open | E14: High | F14: Phase 0
A15: 14 | B15: Is Each BU have different workflow for approval ? | C15: Comms Visioneers | D15: Open | E15: High | F15: Phase 1
A16: 15 | B16: Should add Admin UI to be part of Portal ? | C16: Comms Visioneers | D16: Open | E16: High | F16: Phase 1
A17: 16 | B17: Do you need to support Brand Conflict so a creator can't be selected if already used with a competitor client? | C17: Comms Visioneers | D17: Open | E17: High | F17: Phase 1
A18: 17 | B18: We do have project VSupplier where a supplier/creator can access their data and see all projects linked with them and see all payments and pending payments for each project. Will this be updated too with Creator DB? | C18: Comms Visioneers | D18: Open | E18: Medium | F18: Phase 1
A19: 18 | B19: For a creator, we can have an Agent that manages him/her. Do we care about the agent? Setup already used in VPortal? | C19: Comms Visioneers | D19: Open | E19: Medium | F19: Phase 1
A20: 19 | B20: For the Client Portal, what are the requirements — is it only to create a quotation, and then VCI Portal will verify? | C20: Comms Visioneers | D20: Open | E20: High | F20: Phase 1
A21: 20 | B21: Why do we need to have a separate instance with a different URL? | C21: Comms Visioneers | D21: Open | E21: Medium | F21: Phase 1

Sheet Assumptions
A1: # | B1: Assumption | C1: Impact if Wrong | D1: Phase | E1: Status
A2: 1 | B2: Existing creator data in VPortal Supplier table is accurate and serves as initial roster | C2: Need data cleanup before launch; delay Phase 1 | D2: Phase 1 | E2: Assumed
A3: 2 | B3: Social Blade API key is available and active with sufficient rate limits | C3: Social metrics unavailable until key provisioned | D3: Phase 1 | E3: Confirmed
A4: 3 | B4: VPortal Identity module will be used to authenticate VCI | C4: Need custom auth implementation; delay Phase 0 | D4: Phase 0 | E4: To Verify
A5: 4 | B5: Phyllo account will be set up before Phase 1 development | C5: Social data limited to Social Blade only; reduced quality | D5: Phase 1 | E5: To Verify
A6: 5 | B6: Claude API subscription provisioned before Phase 2 | C6: AI features cannot be tested or deployed | D6: Phase 2 | E6: To Verify
A7: 6 | B7: Visioneers will provide BU branding assets (logos, colors, fonts) before Phase 1 proposal module | C7: Default template only; BU-specific templates delayed | D7: Phase 1 | E7: To Verify
A8: 7 | B8: Visioneers will define approval chain configurations before Phase 1 | C8: Approval workflow ships with placeholder/default config | D8: Phase 1 | E8: To Verify
A9: 8 | B9: Historical PM project data contains sufficient creator cost and deliverable info for rate calculation | C9: Rate calculation produces inaccurate or no results; manual only | D9: Phase 1 | E9: To Verify
A10: 9 | B10: Internal teams work primarily in English; Arabic needed for proposals only | C10: Arabic RTL UI needed earlier than Phase 3 | D10: Phase 1 | E10: Assumed
A11: 10 | B11: Claude Code (AI-assisted development) significantly accelerates development velocity | C11: Timeline estimates may be optimistic | D11: All | E11: Assumed
A12: 11 | B12: VPortal Admin/Manager/Viewer role structure maps to VCI RBAC needs | C12: Need custom role definitions; additional auth work | D12: Phase 0 | E12: To Verify
A13: 12 | B13: Azure Blob Storage is already provisioned and accessible from VPortal API | C13: Need new storage account setup; delay Phase 0 | D13: Phase 0 | E13: Confirmed
A14: 13 | B14: All IP (code, data, AI prompts) belongs to Visioneers from day one | C14: Contract/legal review needed | D14: All | E14: Assumed
B15: Will use same database and Application service in azure for Vportal so there is no additional cost for hosting | C15: Hosting in Azure | D15: All | E15: Confirmed

Sheet Variables
A1: Flat Cost Per Hour | B1: 20
A2: Hours per day | B2: 7
A3: Hour per week | B3: =B2*5 -> 35
